<?xml version="1.0" encoding="UTF-8"?>
<testsuite name="merge"
           tests="24"
           failures="24"
           errors="0"
           skipped="0"
           time="247.568">
    <properties></properties>

            <testcase
                name="test3"
                time="9.258"
                classname="tests.tenant.authentication.api.APIPushFallbackTest">

            <failure type="java.lang.AssertionError" message="{&quot;transaction-id&quot;: &quot;0cf2cc7dce0f4e50bbce040f645a87ac&quot;, &quot;code&quot;: &quot;ACCESS_DENIED&quot;, &quot;reply-message&quot;: &quot;Invalid credentials, please make sure your username and password/otp are correct&quot;} expected [200] but found [401]">
                <![CDATA[java.lang.AssertionError: {"transaction-id": "0cf2cc7dce0f4e50bbce040f645a87ac", "code": "ACCESS_DENIED", "reply-message": "Invalid credentials, please make sure your username and password/otp are correct"} expected [200] but found [401]
                org.testng.Assert.fail(Assert.java:110)org.testng.Assert.failNotEquals(Assert.java:1413)org.testng.Assert.assertEqualsImpl(Assert.java:149)org.testng.Assert.assertEquals(Assert.java:131)org.testng.Assert.assertEquals(Assert.java:1240)tests.tenant.MobileSimulator.registerTOTP(MobileSimulator.java:301)tests.tenant.authentication.api.APIPushFallbackTest.test3(APIPushFallbackTest.java:78)java.base/jdk.internal.reflect.NativeMethodAccessorImpl.invoke0(Native Method)java.base/jdk.internal.reflect.NativeMethodAccessorImpl.invoke(NativeMethodAccessorImpl.java:77)java.base/jdk.internal.reflect.DelegatingMethodAccessorImpl.invoke(DelegatingMethodAccessorImpl.java:43)java.base/java.lang.reflect.Method.invoke(Method.java:568)org.testng.internal.invokers.MethodInvocationHelper.invokeMethod(MethodInvocationHelper.java:135)org.testng.internal.invokers.TestInvoker.invokeMethod(TestInvoker.java:673)org.testng.internal.invokers.TestInvoker.invokeTestMethod(TestInvoker.java:220)org.testng.internal.invokers.TestMethodWithDataProviderMethodWorker.call(TestMethodWithDataProviderMethodWorker.java:80)org.testng.internal.invokers.TestMethodWithDataProviderMethodWorker.call(TestMethodWithDataProviderMethodWorker.java:17)java.base/java.util.concurrent.FutureTask.run(FutureTask.java:264)java.base/java.util.concurrent.Executors$RunnableAdapter.call(Executors.java:539)java.base/java.util.concurrent.FutureTask.run(FutureTask.java:264)java.base/java.util.concurrent.ThreadPoolExecutor.runWorker(ThreadPoolExecutor.java:1136)java.base/java.util.concurrent.ThreadPoolExecutor$Worker.run(ThreadPoolExecutor.java:635)java.base/java.lang.Thread.run(Thread.java:840)
]]>
            </failure>
    </testcase>
            <testcase
                name="test6"
                time="9.959"
                classname="tests.tenant.authentication.api.APIPushFallbackTest">

            <failure type="java.lang.AssertionError" message="{&quot;transaction-id&quot;: &quot;2731b96ec978476cb9a82a9f1f845cbf&quot;, &quot;code&quot;: &quot;ACCESS_DENIED&quot;, &quot;reply-message&quot;: &quot;Invalid credentials, please make sure your username and password/otp are correct&quot;}  https://qa-sfs-st-v5-01.qa.safewalk.info:8446/api/v1/mobile/registration/authenticate/ expected [200] but found [401]">
                <![CDATA[java.lang.AssertionError: {"transaction-id": "2731b96ec978476cb9a82a9f1f845cbf", "code": "ACCESS_DENIED", "reply-message": "Invalid credentials, please make sure your username and password/otp are correct"}  https://qa-sfs-st-v5-01.qa.safewalk.info:8446/api/v1/mobile/registration/authenticate/ expected [200] but found [401]
                org.testng.Assert.fail(Assert.java:110)org.testng.Assert.failNotEquals(Assert.java:1413)org.testng.Assert.assertEqualsImpl(Assert.java:149)org.testng.Assert.assertEquals(Assert.java:131)org.testng.Assert.assertEquals(Assert.java:1240)tests.tenant.MobileSimulator.registerFastAuth(MobileSimulator.java:86)tests.tenant.authentication.api.APIPushFallbackTest.test6(APIPushFallbackTest.java:173)java.base/jdk.internal.reflect.NativeMethodAccessorImpl.invoke0(Native Method)java.base/jdk.internal.reflect.NativeMethodAccessorImpl.invoke(NativeMethodAccessorImpl.java:77)java.base/jdk.internal.reflect.DelegatingMethodAccessorImpl.invoke(DelegatingMethodAccessorImpl.java:43)java.base/java.lang.reflect.Method.invoke(Method.java:568)org.testng.internal.invokers.MethodInvocationHelper.invokeMethod(MethodInvocationHelper.java:135)org.testng.internal.invokers.TestInvoker.invokeMethod(TestInvoker.java:673)org.testng.internal.invokers.TestInvoker.invokeTestMethod(TestInvoker.java:220)org.testng.internal.invokers.TestMethodWithDataProviderMethodWorker.call(TestMethodWithDataProviderMethodWorker.java:80)org.testng.internal.invokers.TestMethodWithDataProviderMethodWorker.call(TestMethodWithDataProviderMethodWorker.java:17)java.base/java.util.concurrent.FutureTask.run(FutureTask.java:264)java.base/java.util.concurrent.Executors$RunnableAdapter.call(Executors.java:539)java.base/java.util.concurrent.FutureTask.run(FutureTask.java:264)java.base/java.util.concurrent.ThreadPoolExecutor.runWorker(ThreadPoolExecutor.java:1136)java.base/java.util.concurrent.ThreadPoolExecutor$Worker.run(ThreadPoolExecutor.java:635)java.base/java.lang.Thread.run(Thread.java:840)
]]>
            </failure>
    </testcase>
            <testcase
                name="test7"
                time="10.482"
                classname="tests.tenant.authentication.api.APIPushFallbackTest">

            <failure type="java.lang.AssertionError" message="{&quot;transaction-id&quot;: &quot;df957e4ef05e49c6bba500cff350d006&quot;, &quot;code&quot;: &quot;ACCESS_DENIED&quot;, &quot;reply-message&quot;: &quot;Invalid credentials, please make sure your username and password/otp are correct&quot;}  https://qa-sfs-st-v5-01.qa.safewalk.info:8446/api/v1/mobile/registration/authenticate/ expected [200] but found [401]">
                <![CDATA[java.lang.AssertionError: {"transaction-id": "df957e4ef05e49c6bba500cff350d006", "code": "ACCESS_DENIED", "reply-message": "Invalid credentials, please make sure your username and password/otp are correct"}  https://qa-sfs-st-v5-01.qa.safewalk.info:8446/api/v1/mobile/registration/authenticate/ expected [200] but found [401]
                org.testng.Assert.fail(Assert.java:110)org.testng.Assert.failNotEquals(Assert.java:1413)org.testng.Assert.assertEqualsImpl(Assert.java:149)org.testng.Assert.assertEquals(Assert.java:131)org.testng.Assert.assertEquals(Assert.java:1240)tests.tenant.MobileSimulator.registerFastAuth(MobileSimulator.java:86)tests.tenant.authentication.api.APIPushFallbackTest.test7(APIPushFallbackTest.java:203)java.base/jdk.internal.reflect.NativeMethodAccessorImpl.invoke0(Native Method)java.base/jdk.internal.reflect.NativeMethodAccessorImpl.invoke(NativeMethodAccessorImpl.java:77)java.base/jdk.internal.reflect.DelegatingMethodAccessorImpl.invoke(DelegatingMethodAccessorImpl.java:43)java.base/java.lang.reflect.Method.invoke(Method.java:568)org.testng.internal.invokers.MethodInvocationHelper.invokeMethod(MethodInvocationHelper.java:135)org.testng.internal.invokers.TestInvoker.invokeMethod(TestInvoker.java:673)org.testng.internal.invokers.TestInvoker.invokeTestMethod(TestInvoker.java:220)org.testng.internal.invokers.TestMethodWithDataProviderMethodWorker.call(TestMethodWithDataProviderMethodWorker.java:80)org.testng.internal.invokers.TestMethodWithDataProviderMethodWorker.call(TestMethodWithDataProviderMethodWorker.java:17)java.base/java.util.concurrent.FutureTask.run(FutureTask.java:264)java.base/java.util.concurrent.Executors$RunnableAdapter.call(Executors.java:539)java.base/java.util.concurrent.FutureTask.run(FutureTask.java:264)java.base/java.util.concurrent.ThreadPoolExecutor.runWorker(ThreadPoolExecutor.java:1136)java.base/java.util.concurrent.ThreadPoolExecutor$Worker.run(ThreadPoolExecutor.java:635)java.base/java.lang.Thread.run(Thread.java:840)
]]>
            </failure>
    </testcase>
            <testcase
                name="test2"
                time="10.348"
                classname="tests.tenant.authentication.api.APIPushFallbackTest">

            <failure type="java.lang.AssertionError" message="{&quot;transaction-id&quot;: &quot;e85d37e175b849e4817b42731c60d796&quot;, &quot;code&quot;: &quot;ACCESS_DENIED&quot;, &quot;reply-message&quot;: &quot;Invalid credentials, please make sure your username and password/otp are correct&quot;} expected [200] but found [401]">
                <![CDATA[java.lang.AssertionError: {"transaction-id": "e85d37e175b849e4817b42731c60d796", "code": "ACCESS_DENIED", "reply-message": "Invalid credentials, please make sure your username and password/otp are correct"} expected [200] but found [401]
                org.testng.Assert.fail(Assert.java:110)org.testng.Assert.failNotEquals(Assert.java:1413)org.testng.Assert.assertEqualsImpl(Assert.java:149)org.testng.Assert.assertEquals(Assert.java:131)org.testng.Assert.assertEquals(Assert.java:1240)tests.tenant.MobileSimulator.registerTOTP(MobileSimulator.java:301)tests.tenant.authentication.api.APIPushFallbackTest.test2(APIPushFallbackTest.java:49)java.base/jdk.internal.reflect.NativeMethodAccessorImpl.invoke0(Native Method)java.base/jdk.internal.reflect.NativeMethodAccessorImpl.invoke(NativeMethodAccessorImpl.java:77)java.base/jdk.internal.reflect.DelegatingMethodAccessorImpl.invoke(DelegatingMethodAccessorImpl.java:43)java.base/java.lang.reflect.Method.invoke(Method.java:568)org.testng.internal.invokers.MethodInvocationHelper.invokeMethod(MethodInvocationHelper.java:135)org.testng.internal.invokers.TestInvoker.invokeMethod(TestInvoker.java:673)org.testng.internal.invokers.TestInvoker.invokeTestMethod(TestInvoker.java:220)org.testng.internal.invokers.TestMethodWithDataProviderMethodWorker.call(TestMethodWithDataProviderMethodWorker.java:80)org.testng.internal.invokers.TestMethodWithDataProviderMethodWorker.call(TestMethodWithDataProviderMethodWorker.java:17)java.base/java.util.concurrent.FutureTask.run(FutureTask.java:264)java.base/java.util.concurrent.Executors$RunnableAdapter.call(Executors.java:539)java.base/java.util.concurrent.FutureTask.run(FutureTask.java:264)java.base/java.util.concurrent.ThreadPoolExecutor.runWorker(ThreadPoolExecutor.java:1136)java.base/java.util.concurrent.ThreadPoolExecutor$Worker.run(ThreadPoolExecutor.java:635)java.base/java.lang.Thread.run(Thread.java:840)
]]>
            </failure>
    </testcase>
            <testcase
                name="test4"
                time="11.053"
                classname="tests.tenant.authentication.api.APIPushFallbackTest">

            <failure type="java.lang.AssertionError" message="{&quot;transaction-id&quot;: &quot;289dec8166544301b2d94f0dcdf5fa1f&quot;, &quot;code&quot;: &quot;ACCESS_DENIED&quot;, &quot;reply-message&quot;: &quot;Invalid credentials, please make sure your username and password/otp are correct&quot;}  https://qa-sfs-st-v5-01.qa.safewalk.info:8446/api/v1/mobile/registration/authenticate/ expected [200] but found [401]">
                <![CDATA[java.lang.AssertionError: {"transaction-id": "289dec8166544301b2d94f0dcdf5fa1f", "code": "ACCESS_DENIED", "reply-message": "Invalid credentials, please make sure your username and password/otp are correct"}  https://qa-sfs-st-v5-01.qa.safewalk.info:8446/api/v1/mobile/registration/authenticate/ expected [200] but found [401]
                org.testng.Assert.fail(Assert.java:110)org.testng.Assert.failNotEquals(Assert.java:1413)org.testng.Assert.assertEqualsImpl(Assert.java:149)org.testng.Assert.assertEquals(Assert.java:131)org.testng.Assert.assertEquals(Assert.java:1240)tests.tenant.MobileSimulator.registerFastAuth(MobileSimulator.java:86)tests.tenant.authentication.api.APIPushFallbackTest.test4(APIPushFallbackTest.java:115)java.base/jdk.internal.reflect.NativeMethodAccessorImpl.invoke0(Native Method)java.base/jdk.internal.reflect.NativeMethodAccessorImpl.invoke(NativeMethodAccessorImpl.java:77)java.base/jdk.internal.reflect.DelegatingMethodAccessorImpl.invoke(DelegatingMethodAccessorImpl.java:43)java.base/java.lang.reflect.Method.invoke(Method.java:568)org.testng.internal.invokers.MethodInvocationHelper.invokeMethod(MethodInvocationHelper.java:135)org.testng.internal.invokers.TestInvoker.invokeMethod(TestInvoker.java:673)org.testng.internal.invokers.TestInvoker.invokeTestMethod(TestInvoker.java:220)org.testng.internal.invokers.TestMethodWithDataProviderMethodWorker.call(TestMethodWithDataProviderMethodWorker.java:80)org.testng.internal.invokers.TestMethodWithDataProviderMethodWorker.call(TestMethodWithDataProviderMethodWorker.java:17)java.base/java.util.concurrent.FutureTask.run(FutureTask.java:264)java.base/java.util.concurrent.Executors$RunnableAdapter.call(Executors.java:539)java.base/java.util.concurrent.FutureTask.run(FutureTask.java:264)java.base/java.util.concurrent.ThreadPoolExecutor.runWorker(ThreadPoolExecutor.java:1136)java.base/java.util.concurrent.ThreadPoolExecutor$Worker.run(ThreadPoolExecutor.java:635)java.base/java.lang.Thread.run(Thread.java:840)
]]>
            </failure>
    </testcase>
            <testcase
                name="test5"
                time="10.972"
                classname="tests.tenant.authentication.api.APIPushFallbackTest">

            <failure type="java.lang.AssertionError" message="{&quot;transaction-id&quot;: &quot;4f15d34e86854d998bac79d1588d28a6&quot;, &quot;code&quot;: &quot;ACCESS_DENIED&quot;, &quot;reply-message&quot;: &quot;Invalid credentials, please make sure your username and password/otp are correct&quot;}  https://qa-sfs-st-v5-01.qa.safewalk.info:8446/api/v1/mobile/registration/authenticate/ expected [200] but found [401]">
                <![CDATA[java.lang.AssertionError: {"transaction-id": "4f15d34e86854d998bac79d1588d28a6", "code": "ACCESS_DENIED", "reply-message": "Invalid credentials, please make sure your username and password/otp are correct"}  https://qa-sfs-st-v5-01.qa.safewalk.info:8446/api/v1/mobile/registration/authenticate/ expected [200] but found [401]
                org.testng.Assert.fail(Assert.java:110)org.testng.Assert.failNotEquals(Assert.java:1413)org.testng.Assert.assertEqualsImpl(Assert.java:149)org.testng.Assert.assertEquals(Assert.java:131)org.testng.Assert.assertEquals(Assert.java:1240)tests.tenant.MobileSimulator.registerFastAuth(MobileSimulator.java:86)tests.tenant.authentication.api.APIPushFallbackTest.test5(APIPushFallbackTest.java:145)java.base/jdk.internal.reflect.NativeMethodAccessorImpl.invoke0(Native Method)java.base/jdk.internal.reflect.NativeMethodAccessorImpl.invoke(NativeMethodAccessorImpl.java:77)java.base/jdk.internal.reflect.DelegatingMethodAccessorImpl.invoke(DelegatingMethodAccessorImpl.java:43)java.base/java.lang.reflect.Method.invoke(Method.java:568)org.testng.internal.invokers.MethodInvocationHelper.invokeMethod(MethodInvocationHelper.java:135)org.testng.internal.invokers.TestInvoker.invokeMethod(TestInvoker.java:673)org.testng.internal.invokers.TestInvoker.invokeTestMethod(TestInvoker.java:220)org.testng.internal.invokers.TestMethodWithDataProviderMethodWorker.call(TestMethodWithDataProviderMethodWorker.java:80)org.testng.internal.invokers.TestMethodWithDataProviderMethodWorker.call(TestMethodWithDataProviderMethodWorker.java:17)java.base/java.util.concurrent.FutureTask.run(FutureTask.java:264)java.base/java.util.concurrent.Executors$RunnableAdapter.call(Executors.java:539)java.base/java.util.concurrent.FutureTask.run(FutureTask.java:264)java.base/java.util.concurrent.ThreadPoolExecutor.runWorker(ThreadPoolExecutor.java:1136)java.base/java.util.concurrent.ThreadPoolExecutor$Worker.run(ThreadPoolExecutor.java:635)java.base/java.lang.Thread.run(Thread.java:840)
]]>
            </failure>
    </testcase>
            <testcase
                name="test2"
                time="10.251"
                classname="tests.tenant.authentication.api.APIPushFallbackTest">

            <failure type="java.lang.AssertionError" message="{&quot;transaction-id&quot;: &quot;37d8e8c6b41c4bcf891453efda146749&quot;, &quot;code&quot;: &quot;ACCESS_DENIED&quot;, &quot;reply-message&quot;: &quot;Invalid credentials, please make sure your username and password/otp are correct&quot;} expected [200] but found [401]">
                <![CDATA[java.lang.AssertionError: {"transaction-id": "37d8e8c6b41c4bcf891453efda146749", "code": "ACCESS_DENIED", "reply-message": "Invalid credentials, please make sure your username and password/otp are correct"} expected [200] but found [401]
                org.testng.Assert.fail(Assert.java:110)org.testng.Assert.failNotEquals(Assert.java:1413)org.testng.Assert.assertEqualsImpl(Assert.java:149)org.testng.Assert.assertEquals(Assert.java:131)org.testng.Assert.assertEquals(Assert.java:1240)tests.tenant.MobileSimulator.registerTOTP(MobileSimulator.java:301)tests.tenant.authentication.api.APIPushFallbackTest.test2(APIPushFallbackTest.java:49)java.base/jdk.internal.reflect.NativeMethodAccessorImpl.invoke0(Native Method)java.base/jdk.internal.reflect.NativeMethodAccessorImpl.invoke(NativeMethodAccessorImpl.java:77)java.base/jdk.internal.reflect.DelegatingMethodAccessorImpl.invoke(DelegatingMethodAccessorImpl.java:43)java.base/java.lang.reflect.Method.invoke(Method.java:568)org.testng.internal.invokers.MethodInvocationHelper.invokeMethod(MethodInvocationHelper.java:135)org.testng.internal.invokers.TestInvoker.invokeMethod(TestInvoker.java:673)org.testng.internal.invokers.TestInvoker.invokeTestMethod(TestInvoker.java:220)org.testng.internal.invokers.TestMethodWithDataProviderMethodWorker.call(TestMethodWithDataProviderMethodWorker.java:80)org.testng.internal.invokers.TestMethodWithDataProviderMethodWorker.call(TestMethodWithDataProviderMethodWorker.java:17)java.base/java.util.concurrent.FutureTask.run(FutureTask.java:264)java.base/java.util.concurrent.Executors$RunnableAdapter.call(Executors.java:539)java.base/java.util.concurrent.FutureTask.run(FutureTask.java:264)java.base/java.util.concurrent.ThreadPoolExecutor.runWorker(ThreadPoolExecutor.java:1136)java.base/java.util.concurrent.ThreadPoolExecutor$Worker.run(ThreadPoolExecutor.java:635)java.base/java.lang.Thread.run(Thread.java:840)
]]>
            </failure>
    </testcase>
            <testcase
                name="test3"
                time="9.373"
                classname="tests.tenant.authentication.api.APIPushFallbackTest">

            <failure type="java.lang.AssertionError" message="{&quot;transaction-id&quot;: &quot;7a1ed9e693f1414790ee6de9744a2d27&quot;, &quot;code&quot;: &quot;ACCESS_DENIED&quot;, &quot;reply-message&quot;: &quot;Invalid credentials, please make sure your username and password/otp are correct&quot;} expected [200] but found [401]">
                <![CDATA[java.lang.AssertionError: {"transaction-id": "7a1ed9e693f1414790ee6de9744a2d27", "code": "ACCESS_DENIED", "reply-message": "Invalid credentials, please make sure your username and password/otp are correct"} expected [200] but found [401]
                org.testng.Assert.fail(Assert.java:110)org.testng.Assert.failNotEquals(Assert.java:1413)org.testng.Assert.assertEqualsImpl(Assert.java:149)org.testng.Assert.assertEquals(Assert.java:131)org.testng.Assert.assertEquals(Assert.java:1240)tests.tenant.MobileSimulator.registerTOTP(MobileSimulator.java:301)tests.tenant.authentication.api.APIPushFallbackTest.test3(APIPushFallbackTest.java:78)java.base/jdk.internal.reflect.NativeMethodAccessorImpl.invoke0(Native Method)java.base/jdk.internal.reflect.NativeMethodAccessorImpl.invoke(NativeMethodAccessorImpl.java:77)java.base/jdk.internal.reflect.DelegatingMethodAccessorImpl.invoke(DelegatingMethodAccessorImpl.java:43)java.base/java.lang.reflect.Method.invoke(Method.java:568)org.testng.internal.invokers.MethodInvocationHelper.invokeMethod(MethodInvocationHelper.java:135)org.testng.internal.invokers.TestInvoker.invokeMethod(TestInvoker.java:673)org.testng.internal.invokers.TestInvoker.invokeTestMethod(TestInvoker.java:220)org.testng.internal.invokers.TestMethodWithDataProviderMethodWorker.call(TestMethodWithDataProviderMethodWorker.java:80)org.testng.internal.invokers.TestMethodWithDataProviderMethodWorker.call(TestMethodWithDataProviderMethodWorker.java:17)java.base/java.util.concurrent.FutureTask.run(FutureTask.java:264)java.base/java.util.concurrent.Executors$RunnableAdapter.call(Executors.java:539)java.base/java.util.concurrent.FutureTask.run(FutureTask.java:264)java.base/java.util.concurrent.ThreadPoolExecutor.runWorker(ThreadPoolExecutor.java:1136)java.base/java.util.concurrent.ThreadPoolExecutor$Worker.run(ThreadPoolExecutor.java:635)java.base/java.lang.Thread.run(Thread.java:840)
]]>
            </failure>
    </testcase>
            <testcase
                name="test5"
                time="10.992"
                classname="tests.tenant.authentication.api.APIPushFallbackTest">

            <failure type="java.lang.AssertionError" message="{&quot;transaction-id&quot;: &quot;05fdcfd2b02547fb9f14df33f41280e8&quot;, &quot;code&quot;: &quot;ACCESS_DENIED&quot;, &quot;reply-message&quot;: &quot;Invalid credentials, please make sure your username and password/otp are correct&quot;}  https://qa-sfs-st-v5-01.qa.safewalk.info:8446/api/v1/mobile/registration/authenticate/ expected [200] but found [401]">
                <![CDATA[java.lang.AssertionError: {"transaction-id": "05fdcfd2b02547fb9f14df33f41280e8", "code": "ACCESS_DENIED", "reply-message": "Invalid credentials, please make sure your username and password/otp are correct"}  https://qa-sfs-st-v5-01.qa.safewalk.info:8446/api/v1/mobile/registration/authenticate/ expected [200] but found [401]
                org.testng.Assert.fail(Assert.java:110)org.testng.Assert.failNotEquals(Assert.java:1413)org.testng.Assert.assertEqualsImpl(Assert.java:149)org.testng.Assert.assertEquals(Assert.java:131)org.testng.Assert.assertEquals(Assert.java:1240)tests.tenant.MobileSimulator.registerFastAuth(MobileSimulator.java:86)tests.tenant.authentication.api.APIPushFallbackTest.test5(APIPushFallbackTest.java:145)java.base/jdk.internal.reflect.NativeMethodAccessorImpl.invoke0(Native Method)java.base/jdk.internal.reflect.NativeMethodAccessorImpl.invoke(NativeMethodAccessorImpl.java:77)java.base/jdk.internal.reflect.DelegatingMethodAccessorImpl.invoke(DelegatingMethodAccessorImpl.java:43)java.base/java.lang.reflect.Method.invoke(Method.java:568)org.testng.internal.invokers.MethodInvocationHelper.invokeMethod(MethodInvocationHelper.java:135)org.testng.internal.invokers.TestInvoker.invokeMethod(TestInvoker.java:673)org.testng.internal.invokers.TestInvoker.invokeTestMethod(TestInvoker.java:220)org.testng.internal.invokers.TestMethodWithDataProviderMethodWorker.call(TestMethodWithDataProviderMethodWorker.java:80)org.testng.internal.invokers.TestMethodWithDataProviderMethodWorker.call(TestMethodWithDataProviderMethodWorker.java:17)java.base/java.util.concurrent.FutureTask.run(FutureTask.java:264)java.base/java.util.concurrent.Executors$RunnableAdapter.call(Executors.java:539)java.base/java.util.concurrent.FutureTask.run(FutureTask.java:264)java.base/java.util.concurrent.ThreadPoolExecutor.runWorker(ThreadPoolExecutor.java:1136)java.base/java.util.concurrent.ThreadPoolExecutor$Worker.run(ThreadPoolExecutor.java:635)java.base/java.lang.Thread.run(Thread.java:840)
]]>
            </failure>
    </testcase>
            <testcase
                name="test7"
                time="10.377"
                classname="tests.tenant.authentication.api.APIPushFallbackTest">

            <failure type="java.lang.AssertionError" message="{&quot;transaction-id&quot;: &quot;5eb04af4456e44faab0b49c61d5539d8&quot;, &quot;code&quot;: &quot;ACCESS_DENIED&quot;, &quot;reply-message&quot;: &quot;Invalid credentials, please make sure your username and password/otp are correct&quot;}  https://qa-sfs-st-v5-01.qa.safewalk.info:8446/api/v1/mobile/registration/authenticate/ expected [200] but found [401]">
                <![CDATA[java.lang.AssertionError: {"transaction-id": "5eb04af4456e44faab0b49c61d5539d8", "code": "ACCESS_DENIED", "reply-message": "Invalid credentials, please make sure your username and password/otp are correct"}  https://qa-sfs-st-v5-01.qa.safewalk.info:8446/api/v1/mobile/registration/authenticate/ expected [200] but found [401]
                org.testng.Assert.fail(Assert.java:110)org.testng.Assert.failNotEquals(Assert.java:1413)org.testng.Assert.assertEqualsImpl(Assert.java:149)org.testng.Assert.assertEquals(Assert.java:131)org.testng.Assert.assertEquals(Assert.java:1240)tests.tenant.MobileSimulator.registerFastAuth(MobileSimulator.java:86)tests.tenant.authentication.api.APIPushFallbackTest.test7(APIPushFallbackTest.java:203)java.base/jdk.internal.reflect.NativeMethodAccessorImpl.invoke0(Native Method)java.base/jdk.internal.reflect.NativeMethodAccessorImpl.invoke(NativeMethodAccessorImpl.java:77)java.base/jdk.internal.reflect.DelegatingMethodAccessorImpl.invoke(DelegatingMethodAccessorImpl.java:43)java.base/java.lang.reflect.Method.invoke(Method.java:568)org.testng.internal.invokers.MethodInvocationHelper.invokeMethod(MethodInvocationHelper.java:135)org.testng.internal.invokers.TestInvoker.invokeMethod(TestInvoker.java:673)org.testng.internal.invokers.TestInvoker.invokeTestMethod(TestInvoker.java:220)org.testng.internal.invokers.TestMethodWithDataProviderMethodWorker.call(TestMethodWithDataProviderMethodWorker.java:80)org.testng.internal.invokers.TestMethodWithDataProviderMethodWorker.call(TestMethodWithDataProviderMethodWorker.java:17)java.base/java.util.concurrent.FutureTask.run(FutureTask.java:264)java.base/java.util.concurrent.Executors$RunnableAdapter.call(Executors.java:539)java.base/java.util.concurrent.FutureTask.run(FutureTask.java:264)java.base/java.util.concurrent.ThreadPoolExecutor.runWorker(ThreadPoolExecutor.java:1136)java.base/java.util.concurrent.ThreadPoolExecutor$Worker.run(ThreadPoolExecutor.java:635)java.base/java.lang.Thread.run(Thread.java:840)
]]>
            </failure>
    </testcase>
            <testcase
                name="test4"
                time="11.059"
                classname="tests.tenant.authentication.api.APIPushFallbackTest">

            <failure type="java.lang.AssertionError" message="{&quot;transaction-id&quot;: &quot;e0ab88b1d06840a0953ce3f757f03571&quot;, &quot;code&quot;: &quot;ACCESS_DENIED&quot;, &quot;reply-message&quot;: &quot;Invalid credentials, please make sure your username and password/otp are correct&quot;}  https://qa-sfs-st-v5-01.qa.safewalk.info:8446/api/v1/mobile/registration/authenticate/ expected [200] but found [401]">
                <![CDATA[java.lang.AssertionError: {"transaction-id": "e0ab88b1d06840a0953ce3f757f03571", "code": "ACCESS_DENIED", "reply-message": "Invalid credentials, please make sure your username and password/otp are correct"}  https://qa-sfs-st-v5-01.qa.safewalk.info:8446/api/v1/mobile/registration/authenticate/ expected [200] but found [401]
                org.testng.Assert.fail(Assert.java:110)org.testng.Assert.failNotEquals(Assert.java:1413)org.testng.Assert.assertEqualsImpl(Assert.java:149)org.testng.Assert.assertEquals(Assert.java:131)org.testng.Assert.assertEquals(Assert.java:1240)tests.tenant.MobileSimulator.registerFastAuth(MobileSimulator.java:86)tests.tenant.authentication.api.APIPushFallbackTest.test4(APIPushFallbackTest.java:115)java.base/jdk.internal.reflect.NativeMethodAccessorImpl.invoke0(Native Method)java.base/jdk.internal.reflect.NativeMethodAccessorImpl.invoke(NativeMethodAccessorImpl.java:77)java.base/jdk.internal.reflect.DelegatingMethodAccessorImpl.invoke(DelegatingMethodAccessorImpl.java:43)java.base/java.lang.reflect.Method.invoke(Method.java:568)org.testng.internal.invokers.MethodInvocationHelper.invokeMethod(MethodInvocationHelper.java:135)org.testng.internal.invokers.TestInvoker.invokeMethod(TestInvoker.java:673)org.testng.internal.invokers.TestInvoker.invokeTestMethod(TestInvoker.java:220)org.testng.internal.invokers.TestMethodWithDataProviderMethodWorker.call(TestMethodWithDataProviderMethodWorker.java:80)org.testng.internal.invokers.TestMethodWithDataProviderMethodWorker.call(TestMethodWithDataProviderMethodWorker.java:17)java.base/java.util.concurrent.FutureTask.run(FutureTask.java:264)java.base/java.util.concurrent.Executors$RunnableAdapter.call(Executors.java:539)java.base/java.util.concurrent.FutureTask.run(FutureTask.java:264)java.base/java.util.concurrent.ThreadPoolExecutor.runWorker(ThreadPoolExecutor.java:1136)java.base/java.util.concurrent.ThreadPoolExecutor$Worker.run(ThreadPoolExecutor.java:635)java.base/java.lang.Thread.run(Thread.java:840)
]]>
            </failure>
    </testcase>
            <testcase
                name="test2"
                time="10.131"
                classname="tests.tenant.authentication.api.APIPushFallbackTest">

            <failure type="java.lang.AssertionError" message="{&quot;transaction-id&quot;: &quot;e827fcbcdee74c15b8c835aace7723f5&quot;, &quot;code&quot;: &quot;ACCESS_DENIED&quot;, &quot;reply-message&quot;: &quot;Invalid credentials, please make sure your username and password/otp are correct&quot;} expected [200] but found [401]">
                <![CDATA[java.lang.AssertionError: {"transaction-id": "e827fcbcdee74c15b8c835aace7723f5", "code": "ACCESS_DENIED", "reply-message": "Invalid credentials, please make sure your username and password/otp are correct"} expected [200] but found [401]
                org.testng.Assert.fail(Assert.java:110)org.testng.Assert.failNotEquals(Assert.java:1413)org.testng.Assert.assertEqualsImpl(Assert.java:149)org.testng.Assert.assertEquals(Assert.java:131)org.testng.Assert.assertEquals(Assert.java:1240)tests.tenant.MobileSimulator.registerTOTP(MobileSimulator.java:301)tests.tenant.authentication.api.APIPushFallbackTest.test2(APIPushFallbackTest.java:49)java.base/jdk.internal.reflect.NativeMethodAccessorImpl.invoke0(Native Method)java.base/jdk.internal.reflect.NativeMethodAccessorImpl.invoke(NativeMethodAccessorImpl.java:77)java.base/jdk.internal.reflect.DelegatingMethodAccessorImpl.invoke(DelegatingMethodAccessorImpl.java:43)java.base/java.lang.reflect.Method.invoke(Method.java:568)org.testng.internal.invokers.MethodInvocationHelper.invokeMethod(MethodInvocationHelper.java:135)org.testng.internal.invokers.TestInvoker.invokeMethod(TestInvoker.java:673)org.testng.internal.invokers.TestInvoker.invokeTestMethod(TestInvoker.java:220)org.testng.internal.invokers.TestMethodWithDataProviderMethodWorker.call(TestMethodWithDataProviderMethodWorker.java:80)org.testng.internal.invokers.TestMethodWithDataProviderMethodWorker.call(TestMethodWithDataProviderMethodWorker.java:17)java.base/java.util.concurrent.FutureTask.run(FutureTask.java:264)java.base/java.util.concurrent.Executors$RunnableAdapter.call(Executors.java:539)java.base/java.util.concurrent.FutureTask.run(FutureTask.java:264)java.base/java.util.concurrent.ThreadPoolExecutor.runWorker(ThreadPoolExecutor.java:1136)java.base/java.util.concurrent.ThreadPoolExecutor$Worker.run(ThreadPoolExecutor.java:635)java.base/java.lang.Thread.run(Thread.java:840)
]]>
            </failure>
    </testcase>
            <testcase
                name="test5"
                time="10.762"
                classname="tests.tenant.authentication.api.APIPushFallbackTest">

            <failure type="java.lang.AssertionError" message="{&quot;transaction-id&quot;: &quot;082b0508a7fa482c8aa488400012df69&quot;, &quot;code&quot;: &quot;ACCESS_DENIED&quot;, &quot;reply-message&quot;: &quot;Invalid credentials, please make sure your username and password/otp are correct&quot;}  https://qa-sfs-st-v5-01.qa.safewalk.info:8446/api/v1/mobile/registration/authenticate/ expected [200] but found [401]">
                <![CDATA[java.lang.AssertionError: {"transaction-id": "082b0508a7fa482c8aa488400012df69", "code": "ACCESS_DENIED", "reply-message": "Invalid credentials, please make sure your username and password/otp are correct"}  https://qa-sfs-st-v5-01.qa.safewalk.info:8446/api/v1/mobile/registration/authenticate/ expected [200] but found [401]
                org.testng.Assert.fail(Assert.java:110)org.testng.Assert.failNotEquals(Assert.java:1413)org.testng.Assert.assertEqualsImpl(Assert.java:149)org.testng.Assert.assertEquals(Assert.java:131)org.testng.Assert.assertEquals(Assert.java:1240)tests.tenant.MobileSimulator.registerFastAuth(MobileSimulator.java:86)tests.tenant.authentication.api.APIPushFallbackTest.test5(APIPushFallbackTest.java:145)java.base/jdk.internal.reflect.NativeMethodAccessorImpl.invoke0(Native Method)java.base/jdk.internal.reflect.NativeMethodAccessorImpl.invoke(NativeMethodAccessorImpl.java:77)java.base/jdk.internal.reflect.DelegatingMethodAccessorImpl.invoke(DelegatingMethodAccessorImpl.java:43)java.base/java.lang.reflect.Method.invoke(Method.java:568)org.testng.internal.invokers.MethodInvocationHelper.invokeMethod(MethodInvocationHelper.java:135)org.testng.internal.invokers.TestInvoker.invokeMethod(TestInvoker.java:673)org.testng.internal.invokers.TestInvoker.invokeTestMethod(TestInvoker.java:220)org.testng.internal.invokers.TestMethodWithDataProviderMethodWorker.call(TestMethodWithDataProviderMethodWorker.java:80)org.testng.internal.invokers.TestMethodWithDataProviderMethodWorker.call(TestMethodWithDataProviderMethodWorker.java:17)java.base/java.util.concurrent.FutureTask.run(FutureTask.java:264)java.base/java.util.concurrent.Executors$RunnableAdapter.call(Executors.java:539)java.base/java.util.concurrent.FutureTask.run(FutureTask.java:264)java.base/java.util.concurrent.ThreadPoolExecutor.runWorker(ThreadPoolExecutor.java:1136)java.base/java.util.concurrent.ThreadPoolExecutor$Worker.run(ThreadPoolExecutor.java:635)java.base/java.lang.Thread.run(Thread.java:840)
]]>
            </failure>
    </testcase>
            <testcase
                name="test4"
                time="11.135"
                classname="tests.tenant.authentication.api.APIPushFallbackTest">

            <failure type="java.lang.AssertionError" message="{&quot;transaction-id&quot;: &quot;a550507033fa477890e49e84c9e2c492&quot;, &quot;code&quot;: &quot;ACCESS_DENIED&quot;, &quot;reply-message&quot;: &quot;Invalid credentials, please make sure your username and password/otp are correct&quot;}  https://qa-sfs-st-v5-01.qa.safewalk.info:8446/api/v1/mobile/registration/authenticate/ expected [200] but found [401]">
                <![CDATA[java.lang.AssertionError: {"transaction-id": "a550507033fa477890e49e84c9e2c492", "code": "ACCESS_DENIED", "reply-message": "Invalid credentials, please make sure your username and password/otp are correct"}  https://qa-sfs-st-v5-01.qa.safewalk.info:8446/api/v1/mobile/registration/authenticate/ expected [200] but found [401]
                org.testng.Assert.fail(Assert.java:110)org.testng.Assert.failNotEquals(Assert.java:1413)org.testng.Assert.assertEqualsImpl(Assert.java:149)org.testng.Assert.assertEquals(Assert.java:131)org.testng.Assert.assertEquals(Assert.java:1240)tests.tenant.MobileSimulator.registerFastAuth(MobileSimulator.java:86)tests.tenant.authentication.api.APIPushFallbackTest.test4(APIPushFallbackTest.java:115)java.base/jdk.internal.reflect.NativeMethodAccessorImpl.invoke0(Native Method)java.base/jdk.internal.reflect.NativeMethodAccessorImpl.invoke(NativeMethodAccessorImpl.java:77)java.base/jdk.internal.reflect.DelegatingMethodAccessorImpl.invoke(DelegatingMethodAccessorImpl.java:43)java.base/java.lang.reflect.Method.invoke(Method.java:568)org.testng.internal.invokers.MethodInvocationHelper.invokeMethod(MethodInvocationHelper.java:135)org.testng.internal.invokers.TestInvoker.invokeMethod(TestInvoker.java:673)org.testng.internal.invokers.TestInvoker.invokeTestMethod(TestInvoker.java:220)org.testng.internal.invokers.TestMethodWithDataProviderMethodWorker.call(TestMethodWithDataProviderMethodWorker.java:80)org.testng.internal.invokers.TestMethodWithDataProviderMethodWorker.call(TestMethodWithDataProviderMethodWorker.java:17)java.base/java.util.concurrent.FutureTask.run(FutureTask.java:264)java.base/java.util.concurrent.Executors$RunnableAdapter.call(Executors.java:539)java.base/java.util.concurrent.FutureTask.run(FutureTask.java:264)java.base/java.util.concurrent.ThreadPoolExecutor.runWorker(ThreadPoolExecutor.java:1136)java.base/java.util.concurrent.ThreadPoolExecutor$Worker.run(ThreadPoolExecutor.java:635)java.base/java.lang.Thread.run(Thread.java:840)
]]>
            </failure>
    </testcase>
            <testcase
                name="test6"
                time="9.931"
                classname="tests.tenant.authentication.api.APIPushFallbackTest">

            <failure type="java.lang.AssertionError" message="{&quot;transaction-id&quot;: &quot;b68297da2d25477db83277cf965fee4d&quot;, &quot;code&quot;: &quot;ACCESS_DENIED&quot;, &quot;reply-message&quot;: &quot;Invalid credentials, please make sure your username and password/otp are correct&quot;}  https://qa-sfs-st-v5-01.qa.safewalk.info:8446/api/v1/mobile/registration/authenticate/ expected [200] but found [401]">
                <![CDATA[java.lang.AssertionError: {"transaction-id": "b68297da2d25477db83277cf965fee4d", "code": "ACCESS_DENIED", "reply-message": "Invalid credentials, please make sure your username and password/otp are correct"}  https://qa-sfs-st-v5-01.qa.safewalk.info:8446/api/v1/mobile/registration/authenticate/ expected [200] but found [401]
                org.testng.Assert.fail(Assert.java:110)org.testng.Assert.failNotEquals(Assert.java:1413)org.testng.Assert.assertEqualsImpl(Assert.java:149)org.testng.Assert.assertEquals(Assert.java:131)org.testng.Assert.assertEquals(Assert.java:1240)tests.tenant.MobileSimulator.registerFastAuth(MobileSimulator.java:86)tests.tenant.authentication.api.APIPushFallbackTest.test6(APIPushFallbackTest.java:173)java.base/jdk.internal.reflect.NativeMethodAccessorImpl.invoke0(Native Method)java.base/jdk.internal.reflect.NativeMethodAccessorImpl.invoke(NativeMethodAccessorImpl.java:77)java.base/jdk.internal.reflect.DelegatingMethodAccessorImpl.invoke(DelegatingMethodAccessorImpl.java:43)java.base/java.lang.reflect.Method.invoke(Method.java:568)org.testng.internal.invokers.MethodInvocationHelper.invokeMethod(MethodInvocationHelper.java:135)org.testng.internal.invokers.TestInvoker.invokeMethod(TestInvoker.java:673)org.testng.internal.invokers.TestInvoker.invokeTestMethod(TestInvoker.java:220)org.testng.internal.invokers.TestMethodWithDataProviderMethodWorker.call(TestMethodWithDataProviderMethodWorker.java:80)org.testng.internal.invokers.TestMethodWithDataProviderMethodWorker.call(TestMethodWithDataProviderMethodWorker.java:17)java.base/java.util.concurrent.FutureTask.run(FutureTask.java:264)java.base/java.util.concurrent.Executors$RunnableAdapter.call(Executors.java:539)java.base/java.util.concurrent.FutureTask.run(FutureTask.java:264)java.base/java.util.concurrent.ThreadPoolExecutor.runWorker(ThreadPoolExecutor.java:1136)java.base/java.util.concurrent.ThreadPoolExecutor$Worker.run(ThreadPoolExecutor.java:635)java.base/java.lang.Thread.run(Thread.java:840)
]]>
            </failure>
    </testcase>
            <testcase
                name="test4"
                time="11.100"
                classname="tests.tenant.authentication.api.APIPushFallbackTest">

            <failure type="java.lang.AssertionError" message="{&quot;transaction-id&quot;: &quot;7e17d58edb994c72afee2edb2f3a7cb7&quot;, &quot;code&quot;: &quot;ACCESS_DENIED&quot;, &quot;reply-message&quot;: &quot;Invalid credentials, please make sure your username and password/otp are correct&quot;}  https://qa-sfs-st-v5-01.qa.safewalk.info:8446/api/v1/mobile/registration/authenticate/ expected [200] but found [401]">
                <![CDATA[java.lang.AssertionError: {"transaction-id": "7e17d58edb994c72afee2edb2f3a7cb7", "code": "ACCESS_DENIED", "reply-message": "Invalid credentials, please make sure your username and password/otp are correct"}  https://qa-sfs-st-v5-01.qa.safewalk.info:8446/api/v1/mobile/registration/authenticate/ expected [200] but found [401]
                org.testng.Assert.fail(Assert.java:110)org.testng.Assert.failNotEquals(Assert.java:1413)org.testng.Assert.assertEqualsImpl(Assert.java:149)org.testng.Assert.assertEquals(Assert.java:131)org.testng.Assert.assertEquals(Assert.java:1240)tests.tenant.MobileSimulator.registerFastAuth(MobileSimulator.java:86)tests.tenant.authentication.api.APIPushFallbackTest.test4(APIPushFallbackTest.java:115)java.base/jdk.internal.reflect.NativeMethodAccessorImpl.invoke0(Native Method)java.base/jdk.internal.reflect.NativeMethodAccessorImpl.invoke(NativeMethodAccessorImpl.java:77)java.base/jdk.internal.reflect.DelegatingMethodAccessorImpl.invoke(DelegatingMethodAccessorImpl.java:43)java.base/java.lang.reflect.Method.invoke(Method.java:568)org.testng.internal.invokers.MethodInvocationHelper.invokeMethod(MethodInvocationHelper.java:135)org.testng.internal.invokers.TestInvoker.invokeMethod(TestInvoker.java:673)org.testng.internal.invokers.TestInvoker.invokeTestMethod(TestInvoker.java:220)org.testng.internal.invokers.TestMethodWithDataProviderMethodWorker.call(TestMethodWithDataProviderMethodWorker.java:80)org.testng.internal.invokers.TestMethodWithDataProviderMethodWorker.call(TestMethodWithDataProviderMethodWorker.java:17)java.base/java.util.concurrent.FutureTask.run(FutureTask.java:264)java.base/java.util.concurrent.Executors$RunnableAdapter.call(Executors.java:539)java.base/java.util.concurrent.FutureTask.run(FutureTask.java:264)java.base/java.util.concurrent.ThreadPoolExecutor.runWorker(ThreadPoolExecutor.java:1136)java.base/java.util.concurrent.ThreadPoolExecutor$Worker.run(ThreadPoolExecutor.java:635)java.base/java.lang.Thread.run(Thread.java:840)
]]>
            </failure>
    </testcase>
            <testcase
                name="test2"
                time="10.450"
                classname="tests.tenant.authentication.api.APIPushFallbackTest">

            <failure type="java.lang.AssertionError" message="{&quot;transaction-id&quot;: &quot;2bac42a20793482d9a43a7ca76e0f866&quot;, &quot;code&quot;: &quot;ACCESS_DENIED&quot;, &quot;reply-message&quot;: &quot;Invalid credentials, please make sure your username and password/otp are correct&quot;} expected [200] but found [401]">
                <![CDATA[java.lang.AssertionError: {"transaction-id": "2bac42a20793482d9a43a7ca76e0f866", "code": "ACCESS_DENIED", "reply-message": "Invalid credentials, please make sure your username and password/otp are correct"} expected [200] but found [401]
                org.testng.Assert.fail(Assert.java:110)org.testng.Assert.failNotEquals(Assert.java:1413)org.testng.Assert.assertEqualsImpl(Assert.java:149)org.testng.Assert.assertEquals(Assert.java:131)org.testng.Assert.assertEquals(Assert.java:1240)tests.tenant.MobileSimulator.registerTOTP(MobileSimulator.java:301)tests.tenant.authentication.api.APIPushFallbackTest.test2(APIPushFallbackTest.java:49)java.base/jdk.internal.reflect.NativeMethodAccessorImpl.invoke0(Native Method)java.base/jdk.internal.reflect.NativeMethodAccessorImpl.invoke(NativeMethodAccessorImpl.java:77)java.base/jdk.internal.reflect.DelegatingMethodAccessorImpl.invoke(DelegatingMethodAccessorImpl.java:43)java.base/java.lang.reflect.Method.invoke(Method.java:568)org.testng.internal.invokers.MethodInvocationHelper.invokeMethod(MethodInvocationHelper.java:135)org.testng.internal.invokers.TestInvoker.invokeMethod(TestInvoker.java:673)org.testng.internal.invokers.TestInvoker.invokeTestMethod(TestInvoker.java:220)org.testng.internal.invokers.TestMethodWithDataProviderMethodWorker.call(TestMethodWithDataProviderMethodWorker.java:80)org.testng.internal.invokers.TestMethodWithDataProviderMethodWorker.call(TestMethodWithDataProviderMethodWorker.java:17)java.base/java.util.concurrent.FutureTask.run(FutureTask.java:264)java.base/java.util.concurrent.Executors$RunnableAdapter.call(Executors.java:539)java.base/java.util.concurrent.FutureTask.run(FutureTask.java:264)java.base/java.util.concurrent.ThreadPoolExecutor.runWorker(ThreadPoolExecutor.java:1136)java.base/java.util.concurrent.ThreadPoolExecutor$Worker.run(ThreadPoolExecutor.java:635)java.base/java.lang.Thread.run(Thread.java:840)
]]>
            </failure>
    </testcase>
            <testcase
                name="test3"
                time="9.462"
                classname="tests.tenant.authentication.api.APIPushFallbackTest">

            <failure type="java.lang.AssertionError" message="{&quot;transaction-id&quot;: &quot;3a4c7e5983944f3d949b8436ab50bd7f&quot;, &quot;code&quot;: &quot;ACCESS_DENIED&quot;, &quot;reply-message&quot;: &quot;Invalid credentials, please make sure your username and password/otp are correct&quot;} expected [200] but found [401]">
                <![CDATA[java.lang.AssertionError: {"transaction-id": "3a4c7e5983944f3d949b8436ab50bd7f", "code": "ACCESS_DENIED", "reply-message": "Invalid credentials, please make sure your username and password/otp are correct"} expected [200] but found [401]
                org.testng.Assert.fail(Assert.java:110)org.testng.Assert.failNotEquals(Assert.java:1413)org.testng.Assert.assertEqualsImpl(Assert.java:149)org.testng.Assert.assertEquals(Assert.java:131)org.testng.Assert.assertEquals(Assert.java:1240)tests.tenant.MobileSimulator.registerTOTP(MobileSimulator.java:301)tests.tenant.authentication.api.APIPushFallbackTest.test3(APIPushFallbackTest.java:78)java.base/jdk.internal.reflect.NativeMethodAccessorImpl.invoke0(Native Method)java.base/jdk.internal.reflect.NativeMethodAccessorImpl.invoke(NativeMethodAccessorImpl.java:77)java.base/jdk.internal.reflect.DelegatingMethodAccessorImpl.invoke(DelegatingMethodAccessorImpl.java:43)java.base/java.lang.reflect.Method.invoke(Method.java:568)org.testng.internal.invokers.MethodInvocationHelper.invokeMethod(MethodInvocationHelper.java:135)org.testng.internal.invokers.TestInvoker.invokeMethod(TestInvoker.java:673)org.testng.internal.invokers.TestInvoker.invokeTestMethod(TestInvoker.java:220)org.testng.internal.invokers.TestMethodWithDataProviderMethodWorker.call(TestMethodWithDataProviderMethodWorker.java:80)org.testng.internal.invokers.TestMethodWithDataProviderMethodWorker.call(TestMethodWithDataProviderMethodWorker.java:17)java.base/java.util.concurrent.FutureTask.run(FutureTask.java:264)java.base/java.util.concurrent.Executors$RunnableAdapter.call(Executors.java:539)java.base/java.util.concurrent.FutureTask.run(FutureTask.java:264)java.base/java.util.concurrent.ThreadPoolExecutor.runWorker(ThreadPoolExecutor.java:1136)java.base/java.util.concurrent.ThreadPoolExecutor$Worker.run(ThreadPoolExecutor.java:635)java.base/java.lang.Thread.run(Thread.java:840)
]]>
            </failure>
    </testcase>
            <testcase
                name="test5"
                time="10.809"
                classname="tests.tenant.authentication.api.APIPushFallbackTest">

            <failure type="java.lang.AssertionError" message="{&quot;transaction-id&quot;: &quot;8a1b3b397f6c466688cdb60f14b71558&quot;, &quot;code&quot;: &quot;ACCESS_DENIED&quot;, &quot;reply-message&quot;: &quot;Invalid credentials, please make sure your username and password/otp are correct&quot;}  https://qa-sfs-st-v5-01.qa.safewalk.info:8446/api/v1/mobile/registration/authenticate/ expected [200] but found [401]">
                <![CDATA[java.lang.AssertionError: {"transaction-id": "8a1b3b397f6c466688cdb60f14b71558", "code": "ACCESS_DENIED", "reply-message": "Invalid credentials, please make sure your username and password/otp are correct"}  https://qa-sfs-st-v5-01.qa.safewalk.info:8446/api/v1/mobile/registration/authenticate/ expected [200] but found [401]
                org.testng.Assert.fail(Assert.java:110)org.testng.Assert.failNotEquals(Assert.java:1413)org.testng.Assert.assertEqualsImpl(Assert.java:149)org.testng.Assert.assertEquals(Assert.java:131)org.testng.Assert.assertEquals(Assert.java:1240)tests.tenant.MobileSimulator.registerFastAuth(MobileSimulator.java:86)tests.tenant.authentication.api.APIPushFallbackTest.test5(APIPushFallbackTest.java:145)java.base/jdk.internal.reflect.NativeMethodAccessorImpl.invoke0(Native Method)java.base/jdk.internal.reflect.NativeMethodAccessorImpl.invoke(NativeMethodAccessorImpl.java:77)java.base/jdk.internal.reflect.DelegatingMethodAccessorImpl.invoke(DelegatingMethodAccessorImpl.java:43)java.base/java.lang.reflect.Method.invoke(Method.java:568)org.testng.internal.invokers.MethodInvocationHelper.invokeMethod(MethodInvocationHelper.java:135)org.testng.internal.invokers.TestInvoker.invokeMethod(TestInvoker.java:673)org.testng.internal.invokers.TestInvoker.invokeTestMethod(TestInvoker.java:220)org.testng.internal.invokers.TestMethodWithDataProviderMethodWorker.call(TestMethodWithDataProviderMethodWorker.java:80)org.testng.internal.invokers.TestMethodWithDataProviderMethodWorker.call(TestMethodWithDataProviderMethodWorker.java:17)java.base/java.util.concurrent.FutureTask.run(FutureTask.java:264)java.base/java.util.concurrent.Executors$RunnableAdapter.call(Executors.java:539)java.base/java.util.concurrent.FutureTask.run(FutureTask.java:264)java.base/java.util.concurrent.ThreadPoolExecutor.runWorker(ThreadPoolExecutor.java:1136)java.base/java.util.concurrent.ThreadPoolExecutor$Worker.run(ThreadPoolExecutor.java:635)java.base/java.lang.Thread.run(Thread.java:840)
]]>
            </failure>
    </testcase>
            <testcase
                name="test6"
                time="10.088"
                classname="tests.tenant.authentication.api.APIPushFallbackTest">

            <failure type="java.lang.AssertionError" message="{&quot;transaction-id&quot;: &quot;d1ba46c21ca241a4b0d54234c24247ba&quot;, &quot;code&quot;: &quot;ACCESS_DENIED&quot;, &quot;reply-message&quot;: &quot;Invalid credentials, please make sure your username and password/otp are correct&quot;}  https://qa-sfs-st-v5-01.qa.safewalk.info:8446/api/v1/mobile/registration/authenticate/ expected [200] but found [401]">
                <![CDATA[java.lang.AssertionError: {"transaction-id": "d1ba46c21ca241a4b0d54234c24247ba", "code": "ACCESS_DENIED", "reply-message": "Invalid credentials, please make sure your username and password/otp are correct"}  https://qa-sfs-st-v5-01.qa.safewalk.info:8446/api/v1/mobile/registration/authenticate/ expected [200] but found [401]
                org.testng.Assert.fail(Assert.java:110)org.testng.Assert.failNotEquals(Assert.java:1413)org.testng.Assert.assertEqualsImpl(Assert.java:149)org.testng.Assert.assertEquals(Assert.java:131)org.testng.Assert.assertEquals(Assert.java:1240)tests.tenant.MobileSimulator.registerFastAuth(MobileSimulator.java:86)tests.tenant.authentication.api.APIPushFallbackTest.test6(APIPushFallbackTest.java:173)java.base/jdk.internal.reflect.NativeMethodAccessorImpl.invoke0(Native Method)java.base/jdk.internal.reflect.NativeMethodAccessorImpl.invoke(NativeMethodAccessorImpl.java:77)java.base/jdk.internal.reflect.DelegatingMethodAccessorImpl.invoke(DelegatingMethodAccessorImpl.java:43)java.base/java.lang.reflect.Method.invoke(Method.java:568)org.testng.internal.invokers.MethodInvocationHelper.invokeMethod(MethodInvocationHelper.java:135)org.testng.internal.invokers.TestInvoker.invokeMethod(TestInvoker.java:673)org.testng.internal.invokers.TestInvoker.invokeTestMethod(TestInvoker.java:220)org.testng.internal.invokers.TestMethodWithDataProviderMethodWorker.call(TestMethodWithDataProviderMethodWorker.java:80)org.testng.internal.invokers.TestMethodWithDataProviderMethodWorker.call(TestMethodWithDataProviderMethodWorker.java:17)java.base/java.util.concurrent.FutureTask.run(FutureTask.java:264)java.base/java.util.concurrent.Executors$RunnableAdapter.call(Executors.java:539)java.base/java.util.concurrent.FutureTask.run(FutureTask.java:264)java.base/java.util.concurrent.ThreadPoolExecutor.runWorker(ThreadPoolExecutor.java:1136)java.base/java.util.concurrent.ThreadPoolExecutor$Worker.run(ThreadPoolExecutor.java:635)java.base/java.lang.Thread.run(Thread.java:840)
]]>
            </failure>
    </testcase>
            <testcase
                name="test6"
                time="9.860"
                classname="tests.tenant.authentication.api.APIPushFallbackTest">

            <failure type="java.lang.AssertionError" message="{&quot;transaction-id&quot;: &quot;2bbb2639786b4d93a0c099ac183b60e2&quot;, &quot;code&quot;: &quot;ACCESS_DENIED&quot;, &quot;reply-message&quot;: &quot;Invalid credentials, please make sure your username and password/otp are correct&quot;}  https://qa-sfs-st-v5-01.qa.safewalk.info:8446/api/v1/mobile/registration/authenticate/ expected [200] but found [401]">
                <![CDATA[java.lang.AssertionError: {"transaction-id": "2bbb2639786b4d93a0c099ac183b60e2", "code": "ACCESS_DENIED", "reply-message": "Invalid credentials, please make sure your username and password/otp are correct"}  https://qa-sfs-st-v5-01.qa.safewalk.info:8446/api/v1/mobile/registration/authenticate/ expected [200] but found [401]
                org.testng.Assert.fail(Assert.java:110)org.testng.Assert.failNotEquals(Assert.java:1413)org.testng.Assert.assertEqualsImpl(Assert.java:149)org.testng.Assert.assertEquals(Assert.java:131)org.testng.Assert.assertEquals(Assert.java:1240)tests.tenant.MobileSimulator.registerFastAuth(MobileSimulator.java:86)tests.tenant.authentication.api.APIPushFallbackTest.test6(APIPushFallbackTest.java:173)java.base/jdk.internal.reflect.NativeMethodAccessorImpl.invoke0(Native Method)java.base/jdk.internal.reflect.NativeMethodAccessorImpl.invoke(NativeMethodAccessorImpl.java:77)java.base/jdk.internal.reflect.DelegatingMethodAccessorImpl.invoke(DelegatingMethodAccessorImpl.java:43)java.base/java.lang.reflect.Method.invoke(Method.java:568)org.testng.internal.invokers.MethodInvocationHelper.invokeMethod(MethodInvocationHelper.java:135)org.testng.internal.invokers.TestInvoker.invokeMethod(TestInvoker.java:673)org.testng.internal.invokers.TestInvoker.invokeTestMethod(TestInvoker.java:220)org.testng.internal.invokers.TestMethodWithDataProviderMethodWorker.call(TestMethodWithDataProviderMethodWorker.java:80)org.testng.internal.invokers.TestMethodWithDataProviderMethodWorker.call(TestMethodWithDataProviderMethodWorker.java:17)java.base/java.util.concurrent.FutureTask.run(FutureTask.java:264)java.base/java.util.concurrent.Executors$RunnableAdapter.call(Executors.java:539)java.base/java.util.concurrent.FutureTask.run(FutureTask.java:264)java.base/java.util.concurrent.ThreadPoolExecutor.runWorker(ThreadPoolExecutor.java:1136)java.base/java.util.concurrent.ThreadPoolExecutor$Worker.run(ThreadPoolExecutor.java:635)java.base/java.lang.Thread.run(Thread.java:840)
]]>
            </failure>
    </testcase>
            <testcase
                name="test7"
                time="10.233"
                classname="tests.tenant.authentication.api.APIPushFallbackTest">

            <failure type="java.lang.AssertionError" message="{&quot;transaction-id&quot;: &quot;31675bc5b59d446899b3f61d6f496088&quot;, &quot;code&quot;: &quot;ACCESS_DENIED&quot;, &quot;reply-message&quot;: &quot;Invalid credentials, please make sure your username and password/otp are correct&quot;}  https://qa-sfs-st-v5-01.qa.safewalk.info:8446/api/v1/mobile/registration/authenticate/ expected [200] but found [401]">
                <![CDATA[java.lang.AssertionError: {"transaction-id": "31675bc5b59d446899b3f61d6f496088", "code": "ACCESS_DENIED", "reply-message": "Invalid credentials, please make sure your username and password/otp are correct"}  https://qa-sfs-st-v5-01.qa.safewalk.info:8446/api/v1/mobile/registration/authenticate/ expected [200] but found [401]
                org.testng.Assert.fail(Assert.java:110)org.testng.Assert.failNotEquals(Assert.java:1413)org.testng.Assert.assertEqualsImpl(Assert.java:149)org.testng.Assert.assertEquals(Assert.java:131)org.testng.Assert.assertEquals(Assert.java:1240)tests.tenant.MobileSimulator.registerFastAuth(MobileSimulator.java:86)tests.tenant.authentication.api.APIPushFallbackTest.test7(APIPushFallbackTest.java:203)java.base/jdk.internal.reflect.NativeMethodAccessorImpl.invoke0(Native Method)java.base/jdk.internal.reflect.NativeMethodAccessorImpl.invoke(NativeMethodAccessorImpl.java:77)java.base/jdk.internal.reflect.DelegatingMethodAccessorImpl.invoke(DelegatingMethodAccessorImpl.java:43)java.base/java.lang.reflect.Method.invoke(Method.java:568)org.testng.internal.invokers.MethodInvocationHelper.invokeMethod(MethodInvocationHelper.java:135)org.testng.internal.invokers.TestInvoker.invokeMethod(TestInvoker.java:673)org.testng.internal.invokers.TestInvoker.invokeTestMethod(TestInvoker.java:220)org.testng.internal.invokers.TestMethodWithDataProviderMethodWorker.call(TestMethodWithDataProviderMethodWorker.java:80)org.testng.internal.invokers.TestMethodWithDataProviderMethodWorker.call(TestMethodWithDataProviderMethodWorker.java:17)java.base/java.util.concurrent.FutureTask.run(FutureTask.java:264)java.base/java.util.concurrent.Executors$RunnableAdapter.call(Executors.java:539)java.base/java.util.concurrent.FutureTask.run(FutureTask.java:264)java.base/java.util.concurrent.ThreadPoolExecutor.runWorker(ThreadPoolExecutor.java:1136)java.base/java.util.concurrent.ThreadPoolExecutor$Worker.run(ThreadPoolExecutor.java:635)java.base/java.lang.Thread.run(Thread.java:840)
]]>
            </failure>
    </testcase>
            <testcase
                name="test3"
                time="9.219"
                classname="tests.tenant.authentication.api.APIPushFallbackTest">

            <failure type="java.lang.AssertionError" message="{&quot;transaction-id&quot;: &quot;5c9ebeac77fa48ee93435ed242cb5028&quot;, &quot;code&quot;: &quot;ACCESS_DENIED&quot;, &quot;reply-message&quot;: &quot;Invalid credentials, please make sure your username and password/otp are correct&quot;} expected [200] but found [401]">
                <![CDATA[java.lang.AssertionError: {"transaction-id": "5c9ebeac77fa48ee93435ed242cb5028", "code": "ACCESS_DENIED", "reply-message": "Invalid credentials, please make sure your username and password/otp are correct"} expected [200] but found [401]
                org.testng.Assert.fail(Assert.java:110)org.testng.Assert.failNotEquals(Assert.java:1413)org.testng.Assert.assertEqualsImpl(Assert.java:149)org.testng.Assert.assertEquals(Assert.java:131)org.testng.Assert.assertEquals(Assert.java:1240)tests.tenant.MobileSimulator.registerTOTP(MobileSimulator.java:301)tests.tenant.authentication.api.APIPushFallbackTest.test3(APIPushFallbackTest.java:78)java.base/jdk.internal.reflect.NativeMethodAccessorImpl.invoke0(Native Method)java.base/jdk.internal.reflect.NativeMethodAccessorImpl.invoke(NativeMethodAccessorImpl.java:77)java.base/jdk.internal.reflect.DelegatingMethodAccessorImpl.invoke(DelegatingMethodAccessorImpl.java:43)java.base/java.lang.reflect.Method.invoke(Method.java:568)org.testng.internal.invokers.MethodInvocationHelper.invokeMethod(MethodInvocationHelper.java:135)org.testng.internal.invokers.TestInvoker.invokeMethod(TestInvoker.java:673)org.testng.internal.invokers.TestInvoker.invokeTestMethod(TestInvoker.java:220)org.testng.internal.invokers.TestMethodWithDataProviderMethodWorker.call(TestMethodWithDataProviderMethodWorker.java:80)org.testng.internal.invokers.TestMethodWithDataProviderMethodWorker.call(TestMethodWithDataProviderMethodWorker.java:17)java.base/java.util.concurrent.FutureTask.run(FutureTask.java:264)java.base/java.util.concurrent.Executors$RunnableAdapter.call(Executors.java:539)java.base/java.util.concurrent.FutureTask.run(FutureTask.java:264)java.base/java.util.concurrent.ThreadPoolExecutor.runWorker(ThreadPoolExecutor.java:1136)java.base/java.util.concurrent.ThreadPoolExecutor$Worker.run(ThreadPoolExecutor.java:635)java.base/java.lang.Thread.run(Thread.java:840)
]]>
            </failure>
    </testcase>
            <testcase
                name="test7"
                time="10.264"
                classname="tests.tenant.authentication.api.APIPushFallbackTest">

            <failure type="java.lang.AssertionError" message="{&quot;transaction-id&quot;: &quot;24a1903584054e7fa28d0809f5f4eff3&quot;, &quot;code&quot;: &quot;ACCESS_DENIED&quot;, &quot;reply-message&quot;: &quot;Invalid credentials, please make sure your username and password/otp are correct&quot;}  https://qa-sfs-st-v5-01.qa.safewalk.info:8446/api/v1/mobile/registration/authenticate/ expected [200] but found [401]">
                <![CDATA[java.lang.AssertionError: {"transaction-id": "24a1903584054e7fa28d0809f5f4eff3", "code": "ACCESS_DENIED", "reply-message": "Invalid credentials, please make sure your username and password/otp are correct"}  https://qa-sfs-st-v5-01.qa.safewalk.info:8446/api/v1/mobile/registration/authenticate/ expected [200] but found [401]
                org.testng.Assert.fail(Assert.java:110)org.testng.Assert.failNotEquals(Assert.java:1413)org.testng.Assert.assertEqualsImpl(Assert.java:149)org.testng.Assert.assertEquals(Assert.java:131)org.testng.Assert.assertEquals(Assert.java:1240)tests.tenant.MobileSimulator.registerFastAuth(MobileSimulator.java:86)tests.tenant.authentication.api.APIPushFallbackTest.test7(APIPushFallbackTest.java:203)java.base/jdk.internal.reflect.NativeMethodAccessorImpl.invoke0(Native Method)java.base/jdk.internal.reflect.NativeMethodAccessorImpl.invoke(NativeMethodAccessorImpl.java:77)java.base/jdk.internal.reflect.DelegatingMethodAccessorImpl.invoke(DelegatingMethodAccessorImpl.java:43)java.base/java.lang.reflect.Method.invoke(Method.java:568)org.testng.internal.invokers.MethodInvocationHelper.invokeMethod(MethodInvocationHelper.java:135)org.testng.internal.invokers.TestInvoker.invokeMethod(TestInvoker.java:673)org.testng.internal.invokers.TestInvoker.invokeTestMethod(TestInvoker.java:220)org.testng.internal.invokers.TestMethodWithDataProviderMethodWorker.call(TestMethodWithDataProviderMethodWorker.java:80)org.testng.internal.invokers.TestMethodWithDataProviderMethodWorker.call(TestMethodWithDataProviderMethodWorker.java:17)java.base/java.util.concurrent.FutureTask.run(FutureTask.java:264)java.base/java.util.concurrent.Executors$RunnableAdapter.call(Executors.java:539)java.base/java.util.concurrent.FutureTask.run(FutureTask.java:264)java.base/java.util.concurrent.ThreadPoolExecutor.runWorker(ThreadPoolExecutor.java:1136)java.base/java.util.concurrent.ThreadPoolExecutor$Worker.run(ThreadPoolExecutor.java:635)java.base/java.lang.Thread.run(Thread.java:840)
]]>
            </failure>
    </testcase>


</testsuite>
